#异常
发现错误的理想时机是在编译阶段，也就是在试图运行程序之前，然而，编译期间并不能找出所有的错误，余下的问题必须在运行期间解决  
需要错误源能通过某种方式，把适当的信息传递给某个接收者——该接收者将知道如何正确处理这个问题  

----------
----------
##异常概念
异常机制将保证能够捕获错误，并且，只需在一个地方处理错误，即所谓的异常处理程序中，
这种方式不仅节省代码，而且把“描述在正常执行过程中做什么事”的代码和“出了问题怎么办”的代码相分离


---------
##基本异常
异常情形（exceptional condition）是指阻止当前方法或作用城继续执行的问题  
把异常情形与普通问题相区分很重要，所谓的普通问题是指在当前环境下能得到足够的信息，总能处理这个错误；
而对于异常情形，就不能继续下去了，因为在当前环境下无法获得必要的信息来解决问题；
所能做的就是从当前环境跳出，并且把问题提交给上一级环境。这就是抛出异常时所发生的事情

当抛出异常后，首先，同Java中其他对象的创建一样，将使用new在堆上创建异常对象；
然后，当前的执行路径被终止，并且从当前环境中弹出对异常对象的引用；
此时，异常处理机制接管程序，并开始寻找一个恰当的地方来继续执行程序：
这个恰当的地方就是异常处理程序，它的任务是将程序从错误状态中恢复，以使程序能要么换一种方式运行，要么继续运行下去 

异常允许强制程序停止运行，并告诉出现了什么问题，或者（理想状态下）强制程序处理问题，并返回到稳定状态  


---------
##异常参数
与使用Java中的其他对象一样，总是用new在堆上创建异常对象，这也伴随着存储空间的分配和构造器的调用
所有标准异常类都有两个构造器：一个是默认构造器；另一个是接受字符串作为参数，以便能把相关信息放入异常对象的构造器

在使用new创建了异常对象之后，此对象的引用将传给throw。尽管返回的异常对象其类型通常与方法设计的返回类型不同，
但从效果上看，它就像是从方法“返回”的。可以简单地把异常处理看成一种不同的返回机制，
另外还能用抛出异常的方式从当前的作用域退出。在这两种情况下，将会返回一个异常对象，然后退出方法或作用域

异常返回的“地点”与普通方法调用返回的“地点”完全不同
（异常将在一个恰当的异常处理程序中得到解决，它的位置可能离异常被抛出的地方很远，也可能会跨越方法调用栈的许多层次）
对于不同类型的错误，要抛出相应的异常。错误信息可以保存在异常对象内部或者用异常类的名称来暗示，上一层环境通过这些信息来决定如何处理异常
（通常，异常对象中仅有的信息就是异常类型，除此之外不包含任何有意义的内容）


--------
##异常捕获
监控区域（guarded region）：它是一段可能产生异常的代码，并且后面跟着处理这些异常的代码，使用try块创建  
异常处理程序紧跟在try块之后，以关键字catch表示

每个catch子句（异常处理程序）看起来就像是接收一个且仅接收一个特殊类型的参数的方法，可以在处理程序的内部使用标识符（id1，id2等等），这与方法参数的使用很相似，
有时可能用不到标识符，因为异常的类型已经给了你足够的信息来对异常进行处理，但标识符并不可以省略  
当异常被抛出时，异常处理机制将负责搜寻参数与异常类型相匹配的第一个处理程序。然后进入catch子句执行，此时认为异常得到了处理，
一旦catch子句结束，则处理程序的查找过程结束。注意，只有匹配的catch子句才能得到执行；与switch 语句不同  
在try块的内部，许多不同的方法调用可能会产生类型相同的异常，而只需要提供一个针对此类型的异常处理程序

###终止与恢复
异常处理理论上有两种基本模型：终止模型和恢复模型
Java支持终止模型（它是Java和C++所支持的模型）。在这种模型中，将假设错误非常关键，以至于程序无法返回到异常发生的地方继续执行。一旦异常被抛出，就表明错误已无法挽回，也不能回来继续执行  
另一种称为恢复模型。意思是异常处理程序的工作是修正错误，然后重新尝试调用出问题的方法，并认为第二次能成功。对于恢复模型，通常希望异常被处理之后能继续执行程序  
如果想要用Java实现类似恢复的行为，那么在遇见错误时就不能抛出异常，而是调用方法来修正该错误。或者，把 try块放在while循环里，这样就不断地进入try块，直到得到满意的结果（失败重试机制）
恢复模型不是很实用。其中的主要原因可能是它所导致的耦合：恢复性的处理程序需要了解异常抛出的地点，这势必要包含依赖于抛出位置的非通用性代码。这增加了代码编写和维护的困难


--------
##自定义异常
要自定义异常类，必须从已有的异常类继承，最好是选择意思相近的异常类继承

在异常处理程序中，调用了在Throwable类声明（Exception即从此类继承）的printStackTrace0方法，它将打印“从方法调用处直到异常抛出处”的方法调用序列，
可以手动调用e.printStackTrace();

###异常与记录日志
使用java.util.logging工具将输出记录到日志中


--------
##声明异常
throws
可以声明方法将抛出异常，实际上却不抛出。编译器相信了这个声明，并强制此方法的用户像真的抛出异常那样使用这个方法  
这样做的好处是，为异常先占个位子，以后就可以抛出这种异常而不用修改已有的代码。在定义抽象基类和接口时这种能力很重要，这样派生类或接口实现就能够抛出这些预先声明的异常 


--------
##捕获所有异常
捕获所有异常，所以最好把它放在处理程序列表的末尾，以防它抢在其他处理程序之前先把异常捕获了 

Exception是与编程有关的所有异常类的基类，所以它不会含有太多具体的信息，不过可以调用它从其基类Throwable继承的方法：
//用来获取详细信息，或用本地语言表示的详细信息
String getMessage()
String getLocalizedMessage()  

//返回对Throwable的简单描述，要是有详细信息的话，也会把它包含在内
String toString()

//打印Throwable和Throwable的调用栈轨迹,调用栈显示了“把你带到异常抛出地点”的方法调用序列  
//其中第一个版本输出到标准错误，后两个版本允许选择要输出的流
void printStackTrace(PrintStream)
void printStackTrace(java.io.PrintWriter)

//用于在Throwable对象的内部记录栈帧的当前状态,在程序重新抛出错误或异常时很有用
Throwable fillInStackTrace()

也可以使用Throwable从其基类Object继承的方法,对于异常来说，getClass是个很好用的方法，它将返回一个表示此对象类型的对象,  
然后可以使用getName方法查询这个Class对象包含包信息的名称，或者使用只产生类名称的getSimpleName方法


###多重捕获
Java 7的多重捕获机制，可以将不同类型的异常使用“或”将它们组合起来，只在一个catch块中使用
try {
    x();
} catch(Except1 | Except2 | Except3 | Except4 e) {
    process();
}

try {
    x();
} catch(Except1 | Except2 e) {
    process1();
} catch(Except3 | Except4 e) {
    process2();
}

###栈轨迹
printStackTrace()方法所提供的信息可以通过getStackTrace()方法来直接访问，这个方法将返回一个由栈轨迹中的元素所构成的数组，
其中每一个元素都表示栈中的一桢,元素0是栈顶元素，并且是调用序列中的最后一个方法调用（这个Throwable 被创建和抛出之处）,数组中的最后一个元素和栈底是调用序列中的第一个方法调用
for(StackTraceElement ste : e.getStackTrace())

###重新抛出异常
把刚捕获的异常重新抛出，既然已经得到了对当前异常对象的引用，可以直接把它重新抛出：重抛异常会把异常抛给上一级环境中的异常处理程序，
异常对象的所有信息都得以保持，所以高一级环境中捕获此异常的处理程序可以从这个异常对象中得到所有信息。
如果只是把当前异常对象重新抛出，那么printStackTrace()方法显示的将是原来异常抛出点的调用栈信息，而并非重新抛出点的信息。
要想更新这个信息，可以调用filInStackTrace()方法，这将返回一个Throwable对象，它是通过把当前调用栈信息填入原来那个异常对象而建立的
throw (Exception)e.fillInStackTrace();

调用fillInStackTrace() 的那一行就成了异常的新发生地了  
有可能在捕获异常之后抛出另一种异常，得到的效果类似于使用 filInStackTrace()，有关原来异常发生点的信息会丢失，剩下的是与新的抛出点有关的信息

###精准的重新抛出异常
class BaseException extends Exception {
}

class DerivedException extends BaseException {
}

class DerivedException1 extends BaseException {
}
public class PreciseRethrow {
    //要求捕获的BaseException必须是DerivedException，编译器会检查，JAVA 7支持
    void catcher() throws DerivedException {
        try {
            throw new DerivedException();
        } catch (BaseException e) {
            throw e;
        }
    }
    
    //这种方式是不允许的
    void catcher1() throws DerivedException1{
        try {
            throw new DerivedException();
        } catch (BaseException e) {
            throw e;
        }
    }
}

###异常链
想要在捕获一个异常后抛出另一个异常，并且希望把原始异常的信息保存下来，这被称为异常链。
JDK1.4以后，现在所有Throwable的子类在构造器中都可以接受一个cause对象作为参数，这个cause就用来表示原始异常，
这样通过把原始异常传递给新的异常，使得即使在当前位置创建并抛出了新的异常，也能通过这个异常链追踪到异常最初发生的位置

在Throwable的子类中，只有三种基本的异常类提供了带cause参数的构造器：
Error（用于Java虚拟机报告系统错误）、Exception以及RuntimeException，  
如果要把其他类型的异常链接起来，应该使用initCause0方法而不是构造器


----------
##Java 标准异常
Throwable类被用来表示任何可以作为异常被抛出的类，Throwable对象可分为两种类型：
Error:用来表示编译时和系统错误（除特殊情况外，一般不用你关心）；
Exception 是可以被抛出的基本类型，在Java类库、用户方法以及运行时故障中都可能抛出Exception型异常。

所以Java程序员关心的基类型通常是Exception，这些异常除了名称外其实都差不多。
异常的基本的概念是用名称代表发生的问题，并且异常的名称应该可以望文知意

在编译时被强制检查的异常称为被检查的异常
运行时异常RuntimeException(包括子类)，不受检查异常

运行时异常会自动被lava虚拟机抛出，所以不必在声明方法中把它们列出来，运行时异常将被自动捕获
RuntimeException代表的是编程错误：
1.无法预料的错误。比如从控制范围之外传递进来的null引用。
2.应该在代码中进行检查的错误，（数组溢出）在一个地方发生的异常，常常会在另一个地方导致错误

只能在代码中忽略RuntimeException（及其子类）类型的异常，因为所有受检查类型异常的处理都是由编译器强制实施的


-------------
##finally
当要把除内存之外的资源恢复到它们的初始状态时，就要用到finally子句 
这种需要清理的资源包括：已经打开的文件或网络连接，在屏幕上画的图形，甚至可以是外部世界的某个开关

###异常丢失
1.前一个异常还没处理就抛出下一个异常的情形,这是糟糕的编程错误，使用finally中也会抛出异常的场景y特别注意
2.从finally语句调用return

class VeryImportantException extends Exception {
    @Override
    public String toString() {
        return "A very important exception!";
    }
}
class HoHumException extends Exception {
    @Override
    public String toString() {
        return "A trivial exception";
    }
}
public class LostMessage {
    void f() throws VeryImportantException {
        throw new VeryImportantException();
    }
    void dispose() throws HoHumException {
        throw new HoHumException();
    }
    public static void main(String[] args) {
        try {
            LostMessage lm = new LostMessage();
            try {
                lm.f(); //VeryImportantException不见了，它被finally子句里的HoHumException所取代
            } finally {
                lm.dispose();
            }
        } catch(VeryImportantException | HoHumException e) {
            System.out.println(e);
        }
    }
}


------------
##Try-With-Resources用法
Java 7引入了try-with-resources语法
public static void main(String[] args) {
    InputStream in = null;
    try {
        in = new FileInputStream(new File("MessyExceptions.java"));
        int contents = in.read();
        // Process contents
    } catch(IOException e) {
        // Handle the error
    } finally {
        if(in != null) {
            try {
                in.close();
            } catch(IOException e) {
                // Handle the close() error
            }
        }
    }
}

 public static void main(String[] args) {
  try(InputStream in = new FileInputStream(new File("TryWithResources.java"))) 
  {
      int contents = in.read();
      // Process contents
  } catch(IOException e) {
      // Handle the error
  }
}

try-with-resources执行顺序：资源规范头->逻辑体->close()资源关闭->catch捕获异常处理程序->finally

在try-with-resources定义子句中创建的对象（在括号内）必须实现java.lang.Autocloseable接口，接口有一个方法，close()。
资源规范头中可以包含多个定义，并且通过分号进行分割（最后一个分号是可选的）,规范头中定义的每个对象都会在try语句块运行结束之后调用close()方法
try-with-resources里面的try语句块可以不包含catch或者finally语句而独立存在
Java 5中的Closeable已经被修改，修改之后的接口继承了AutoCloseable接口。所以所有实现了Closeable接口的对象，都支持了try-with-resources特性  

正常场景，逻辑执行完成（没有出现异常），调用资源的关闭
退出try块会调用对象的close()方法，并以与创建顺序相反的顺序关闭它们，顺序很重要，对象可能依赖关系
资源规范头中间出现异常（构造器异常），会关闭之前的资源，然后进入捕获的异常处理程序
close抛出异常，依旧会关闭其他资源，然后进入异常处理程序

注意：只会关闭资源规范头中的资源

try-with-resources关闭时先后抛出抛出多个异常，只会抛出第一个，其他的可通过e.getSuppressed()获得


------------
##异常限制
当覆盖方法的时候，只能抛出在基类方法的异常说明里列出的那些异常(不能超过，子类覆盖方法时可以不抛出异常)，（异常的多态可以生效）
这个限制很有用，当基类使用的代码应用到其派生类对象的时候，一样能够工工作

异常限制对构造器不起作用,构造器可以抛出任何异常，而不必理会基类构造器所抛出的异常。
然而，因为基类构造器必须以这样或那样的方式被调用（这里默认构造器将自动被调用），但派生类构造器的异常说明必须包含基类构造器的异常说明

派生类构造器不能捕获基类构造器抛出的异常,不能调用super时,try-catch

不能基于异常说明来重载方法  
一个出现在基类方法的异常说明中的异常，不一定会出现在派生类方法的异常说明里
在继承和覆盖的过程中，某个特定方法的“异常说明的接口”不是变大了而是变小了


------------
##异常构造
要时刻询问自己“如果异常发生了，所有东西能被正确的清理吗？"尽管大多数情况下是非常安全的，
但涉及构造器时，问题就出现了 构造器会把对象设置成安全的初始状态，但还会有别的动作，
比如打开一个文件，这样的动作只有在对象使用完毕并且用户调用了特殊的清理方法之后才能得以清理。
如果在构造器内抛出了异常，这些清理行为也许就不能正常工作了。这意味着在编写构造器时要格外细心。

也许会认为使用finally就可以解决问题。但问题并非如此简单，因为finally会每次都执行清理代码。
如果构造器在其执行过程中半途而废，也许该对象的某些部分还没有被成功创建，而这些部分在finaly子句中却是要被清理的

不要一味的认为要在finally中关闭资源

尽量避免在构造中异常处理，eg:操作资源


----------
##异常匹配
抛出异常的时候，异常处理系统会按照代码的书写顺序找出“最近”的处理程序，
找到匹配的处理程序之后，它就认为异常将得到处理，然后就不再继续查找。


---------
##异常处理
受检异常存在坏处，不要一直往上传递异常，导致每个方法都声明异常
1.把异常传递给控制台
2.把“被检查的异常”转换为“不检查的异常”


--------
##异常指南
应该在下列情况下使用异常：
1.尽可能使用 try-with-resource。
2.在恰当的级别处理问题。（在知道该如何处理的情况下才捕获异常。）
3.解决问题并且重新调用产生异常的方法。
4.进行少许修补，然后绕过异常发生的地方继续执行。
5.用别的数据进行计算，以代替方法预计会返回的值。
6.把当前运行环境下能做的事情尽量做完，然后把相同的异常重抛到更高层。
7.把当前运行环境下能做的事情尽量做完，然后把不同的异常抛到更高层。
8.终止程序。
9.进行简化。（如果你的异常模式使问题变得太复杂，那用起来会非常痛苦也很烦人）
10.让类库和程序更安全。（这既是在为调试做短期投资，也是在为程序的健壮性做长期投资）

















